<robot name="quadruped" >
  
  <material name="blue">
      <color rgba="0 0 0.5 1" />
  </material>

  <material name="grey">
      <color rgba="0.5 0.5 0.5 1" />
  </material>

  <material name="black">
      <color rgba="0.1 0.1 0.1 1" />
  </material>

  <material name="white">
      <color rgba="1 1 1 1" />
  </material>
  <link name="dummy">
  </link>

  <link name="body">
    <inertial>
      <mass
        value="3.0416" />
      <inertia
        ixx="0.0073301"
        ixy="2.1671E-09"
        ixz="1.9602E-06"
        iyy="0.0077176"
        iyz="-1.1292E-05"
        izz="0.0059691" />
    </inertial>
    <visual>
      <origin rpy="0 0 1.57" xyz="0 0 -0.06"/>
      <geometry>
        <mesh filename="package://quadruped_description/meshes/frame_aluminum_motor.stl" />
      </geometry>
      <material name="grey"/>
    </visual>
    <collision>
      <origin
        xyz="0 0 -0.06"
        rpy="0 0 1.57" />
      <geometry>
        <mesh filename="package://quadruped_description/meshes/frame_aluminum_motor.stl" />
      </geometry>
    </collision>
  </link>

  <joint name="dummy_joint" type="fixed">
     <parent link="dummy"/>
     <child link="body"/>
  </joint>
  
  <link
    name="camera_link">
    <inertial>
      <mass
        value="0.046222" />
      <inertia
        ixx="2.633E-06"
        ixy="-4.2166E-09"
        ixz="1.2531E-08"
        iyy="2.5049E-05"
        iyz="9.9718E-08"
        izz="2.639E-05" />
    </inertial>
    <visual>
      <origin
        xyz="0 0 0"
        rpy="1.57 0 1.57" />
      <geometry>
        <mesh
          filename="package://quadruped_description/meshes/camera_link.stl" />
      </geometry>
      <material
        name="">
        <color
          rgba="0.75294 0.75294 0.75294 1" />
      </material>
    </visual>
    <collision>
      <origin
        xyz="0 0 0"
        rpy="0 0 0" />
      <geometry>
        <mesh
          filename="package://quadruped_description/meshes/camera_link.stl" />
      </geometry>
    </collision>
  </link>

  <joint
    name="camera_joint" type="revolute">
    <origin
      xyz="0.2 0 0.42525"
      rpy="0 0 0" />
    <parent
      link="body" />
    <child
      link="camera_link" />
    <axis
      xyz="0 1 0" />
    <limit
      lower="-3.14"
      upper="3.14"
      effort="100"
      velocity="100" />
  </joint> 

  <link name="front_left_u">
    <inertial>
      <mass value="0.814" />
      <inertia ixx="0.008" ixy="0.0"  ixz="0.001"
               iyy="0.008" iyz="0.001"
               izz="0.001" />
    </inertial>
    <visual>
      <origin rpy="1.57 0 1.57" xyz="0 0 0"/>
      <geometry>
        <mesh filename="package://quadruped_description/meshes/joint_gear_upper_assembly.stl" />
      </geometry>
      <material name="grey"/>
    </visual>
    <collision>
      <origin
        xyz="0 0 0"
        rpy="1.57 0 1.57" />
      <geometry>
        <mesh filename="package://quadruped_description/meshes/joint_gear_upper_assembly.stl" />
      </geometry>
    </collision>
  </link>
  <joint name="front_left_joint1" type="revolute">
    <limit effort="1000.0" lower="-3.14" upper="3.14" velocity="0.5"/>
    <parent link="body"/>
    <child link="front_left_u"/>
    <origin xyz="0.11 0.05 0" rpy="0 0 0" />
    <axis xyz="0 1 0" />
  </joint>

  <link name="front_right_u">
    <inertial>
      <mass value="0.814" />
      <inertia ixx="7701247.352E-09" ixy="96047.710E-09"  ixz="-1228944.675E-09"
               iyy="7801785.041E-09" iyz="550113.749E-09"
               izz="877983.793E-09" />
    </inertial>
    <visual>
      <origin rpy="1.57 3.14 1.57" xyz="0 0 0"/>
      <geometry>
        <mesh filename="package://quadruped_description/meshes/joint_gear_upper_assembly.stl" />
      </geometry>
      <material name="grey"/>
    </visual>
    <collision>
      <origin
        xyz="0 0 0"
        rpy="1.57 3.14 1.57" />
      <geometry>
        <mesh filename="package://quadruped_description/meshes/joint_gear_upper_assembly.stl" />
      </geometry>
    </collision>
  </link>

  <link name="back_left_u">
    <inertial>
      <mass value="0.814" />
      <inertia ixx="7701247.352E-09" ixy="96047.710E-09"  ixz="-1228944.675E-09"
               iyy="7801785.041E-09" iyz="550113.749E-09"
               izz="877983.793E-09" />
    </inertial>
    <visual>
      <origin rpy="1.57 3.14 1.57" xyz="0 0 0"/>
      <geometry>
        <mesh filename="package://quadruped_description/meshes/joint_gear_upper_assembly.stl" />
      </geometry>
      <material name="grey"/>
    </visual>
    <collision>
      <origin
        xyz="0 0 0"
        rpy="1.57 3.14 1.57" />
      <geometry>
        <mesh filename="package://quadruped_description/meshes/joint_gear_upper_assembly.stl" />
      </geometry>
    </collision>
  </link>

  <link name="back_right_u">
    <inertial>
      <mass value="0.814" />
      <inertia ixx="7701247.352E-09" ixy="96047.710E-09"  ixz="-1228944.675E-09"
               iyy="7801785.041E-09" iyz="550113.749E-09"
               izz="877983.793E-09" />
    </inertial>
    <visual>
      <origin rpy="1.57 0 1.57" xyz="0 0 0"/>
      <geometry>
        <mesh filename="package://quadruped_description/meshes/joint_gear_upper_assembly.stl" />
      </geometry>
      <material name="grey"/>
    </visual>
    <collision>
      <origin
        xyz="0 0 0"
        rpy="1.57 0 1.57" />
      <geometry>
        <mesh filename="package://quadruped_description/meshes/joint_gear_upper_assembly.stl" />
      </geometry>
    </collision>
  </link>

  <link name="front_left_d">
    <inertial>
      <mass value="0.5" />
      <inertia ixx="7141392.287E-09" ixy="-13.226E-09"  ixz="-913664.184E-09"
               iyy="7895374.282E-09" iyz="-31.485E-09"
               izz="830881.651E-09" />
    </inertial>
    <visual>
      <origin rpy="1.57 0 1.57" xyz="0 0 0"/>
      <geometry>
        <mesh filename="package://quadruped_description/meshes/Assembly_lower_link_v2.stl" />
      </geometry>
      <material name="grey"/>
    </visual>
    <collision>
      <origin
        xyz="0 0 0"
        rpy="1.57 0 1.57" />
      <geometry>
        <mesh filename="package://quadruped_description/meshes/Assembly_lower_link_v2.stl" />
      </geometry>
    </collision>
  </link>

  <link name="front_right_d">
    <inertial>
      <mass value="0.5" />
      <inertia ixx="7141392.287E-09" ixy="-13.226E-09"  ixz="-913664.184E-09"
               iyy="7895374.282E-09" iyz="-31.485E-09"
               izz="830881.651E-09" />
    </inertial>
    <visual>
      <origin rpy="-1.57 0 -1.57" xyz="0 0 0"/>
      <geometry>
        <mesh filename="package://quadruped_description/meshes/Assembly_lower_link_v2.stl" />
      </geometry>
      <material name="grey"/>
    </visual>
    <collision>
      <origin
        xyz="0 0 0"
        rpy="-1.57 0 -1.57" />
      <geometry>
        <mesh filename="package://quadruped_description/meshes/Assembly_lower_link_v2.stl" />
      </geometry>
    </collision>
  </link>
  
  <link name="back_left_d">
    <inertial>
      <mass value="0.5" />
      <inertia ixx="7141392.287E-09" ixy="-13.226E-09"  ixz="-913664.184E-09"
               iyy="7895374.282E-09" iyz="-31.485E-09"
               izz="830881.651E-09" />
    </inertial>
    <visual>
      <origin rpy="-1.57 0 -1.57" xyz="0 0 0"/>
      <geometry>
        <mesh filename="package://quadruped_description/meshes/Assembly_lower_link_v2.stl" />
      </geometry>
      <material name="grey"/>
    </visual>
    <collision>
      <origin
        xyz="0 0 0"
        rpy="-1.57 0 -1.57" />
      <geometry>
        <mesh filename="package://quadruped_description/meshes/Assembly_lower_link_v2.stl" />
      </geometry>
    </collision>
  </link>
  
  <link name="back_right_d">
    <inertial>
      <mass value="0.5" />
      <inertia ixx="7141392.287E-09" ixy="-13.226E-09"  ixz="-913664.184E-09"
               iyy="7895374.282E-09" iyz="-31.485E-09"
               izz="830881.651E-09" />
    </inertial>
    <visual>
      <origin rpy="1.57 0 1.57" xyz="0 0 0"/>
      <geometry>
        <mesh filename="package://quadruped_description/meshes/Assembly_lower_link_v2.stl" />
      </geometry>
      <material name="grey"/>
    </visual>
    <collision>
      <origin
        xyz="0 0 0"
        rpy="1.57 0 1.57" />
      <geometry>
        <mesh filename="package://quadruped_description/meshes/Assembly_lower_link_v2.stl" />
      </geometry>
    </collision>
  </link>
 
    <joint name="front_right_joint1" type="revolute">
    <limit effort="1000.0" lower="-3.14" upper="3.14" velocity="0.5"/>
    <parent link="body"/>
    <child link="front_right_u"/>
    <origin xyz="0.11 -0.05 0" rpy="0 0 0" />
    <axis xyz="0 1 0" />
  </joint>

  <joint name="front_right_joint2" type="revolute">
    <limit effort="1000.0" lower="-3.14" upper="3.14" velocity="0.5"/>
    <parent link="front_right_u"/>
    <child link="front_right_d"/>
    <origin xyz="0.4 -0.005 0" rpy="0 0 0" />
    <axis xyz="0 1 0" />
  </joint>

  

  <joint name="front_left_joint2" type="revolute">
    <limit effort="1000.0" lower="-3.14" upper="3.14" velocity="0.5"/>
    <parent link="front_left_u"/>
    <child link="front_left_d"/>
    <origin xyz="0.4 0.005 0" rpy="0 0 0" />
    <axis xyz="0 1 0" />
  </joint>

  <joint name="back_left_joint1" type="revolute">
    <limit effort="1000.0" lower="-3.14" upper="3.14" velocity="0.5"/>
    <parent link="body"/>
    <child link="back_left_u"/>
    <origin xyz="-0.11 0.05 0" rpy="0 0 3.14" />
    <axis xyz="0 1 0" />
  </joint>

  <joint name="back_left_joint2" type="revolute">
    <limit effort="1000.0" lower="-3.14" upper="3.14" velocity="0.5"/>
    <parent link="back_left_u"/>
    <child link="back_left_d"/>
    <origin xyz="0.4 -0.005 0" rpy="0 0 0" />
    <axis xyz="0 1 0" />
  </joint>

  <joint name="back_right_joint1" type="revolute">
    <limit effort="1000.0" lower="-3.14" upper="3.14" velocity="0.5"/>
    <parent link="body"/>
    <child link="back_right_u"/>
    <origin xyz="-0.11 -0.05 0" rpy="0 0 3.14" />
    <axis xyz="0 1 0" />
  </joint>  

  <joint name="back_right_joint2" type="revolute">
    <limit effort="1000.0" lower="-3.14" upper="3.14" velocity="0.5"/>
    <parent link="back_right_u"/>
    <child link="back_right_d"/>
    <origin xyz="0.4 0.005 0" rpy="0 0 0" />
    <axis xyz="0 1 0" />
  </joint> 

</robot>