<?xml version="1.0"?>

<robot xmlns:xacro="http://www.ros.org/wiki/xacro">

  <link name="dummy">
  </link>

  <link name="body">
    <inertial>
      <mass value="8.4" />
      <inertia ixx="0.14596" ixy="0.00010"  ixz="0.00013"
               iyy="0.08855" iyz="-0.03467"
               izz="0.11796" />
    </inertial>
    
    <visual>
      <origin rpy="1.57 0 1.57" xyz="0 0 0"/>
      <geometry>
        <mesh filename="model://my_quadruped/meshes/frame_aluminum_motor_case.dae" />
      </geometry>
      <material name="grey"/>
    </visual>
    <collision>
      <origin
        xyz="0 0 0"
        rpy="1.57 0 1.57" />
      <geometry>
        <mesh filename="model://my_quadruped/meshes/frame_aluminum_motor_case.dae" />
      </geometry>
    </collision>
  </link>

  <joint name="dummy_joint" type="fixed">
     <parent link="dummy"/>
     <child link="body"/>
  </joint>

  <link name="front_left_u">
    <inertial>
      <mass value="0.814" />
      <inertia ixx="0.008" ixy="0.0"  ixz="0.001"
               iyy="0.008" iyz="0.001"
               izz="0.001" />
    </inertial>
    <visual>
      <origin rpy="1.57 0 1.57" xyz="0 0 0"/>
      <geometry>
        <mesh filename="model://my_quadruped/meshes/joint_gear_upper_assembly.stl" />
      </geometry>
      <material name="grey"/>
    </visual>
    <collision>
      <origin
        xyz="0 0 0"
        rpy="1.57 0 1.57" />
      <geometry>
        <mesh filename="model://my_quadruped/meshes/joint_gear_upper_assembly.stl" />
      </geometry>
    </collision>
  </link>

  <link name="front_right_u">
    <inertial>
      <mass value="0.814" />
      <inertia ixx="7701247.352E-09" ixy="96047.710E-09"  ixz="-1228944.675E-09"
               iyy="7801785.041E-09" iyz="550113.749E-09"
               izz="877983.793E-09" />
    </inertial>
    <visual>
      <origin rpy="1.57 3.14 1.57" xyz="0 0 0"/>
      <geometry>
        <mesh filename="model://my_quadruped/meshes/joint_gear_upper_assembly.stl" />
      </geometry>
      <material name="grey"/>
    </visual>
    <collision>
      <origin
        xyz="0 0 0"
        rpy="1.57 3.14 1.57" />
      <geometry>
        <mesh filename="model://my_quadruped/meshes/joint_gear_upper_assembly.stl" />
      </geometry>
    </collision>
  </link>

  <link name="back_left_u">
    <inertial>
      <mass value="0.814" />
      <inertia ixx="7701247.352E-09" ixy="96047.710E-09"  ixz="-1228944.675E-09"
               iyy="7801785.041E-09" iyz="550113.749E-09"
               izz="877983.793E-09" />
    </inertial>
    <visual>
      <origin rpy="1.57 3.14 1.57" xyz="0 0 0"/>
      <geometry>
        <mesh filename="model://my_quadruped/meshes/joint_gear_upper_assembly.stl" />
      </geometry>
      <material name="grey"/>
    </visual>
    <collision>
      <origin
        xyz="0 0 0"
        rpy="1.57 3.14 1.57" />
      <geometry>
        <mesh filename="model://my_quadruped/meshes/joint_gear_upper_assembly.stl" />
      </geometry>
    </collision>
  </link>

  <link name="back_right_u">
    <inertial>
      <mass value="0.814" />
      <inertia ixx="7701247.352E-09" ixy="96047.710E-09"  ixz="-1228944.675E-09"
               iyy="7801785.041E-09" iyz="550113.749E-09"
               izz="877983.793E-09" />
    </inertial>
    <visual>
      <origin rpy="1.57 0 1.57" xyz="0 0 0"/>
      <geometry>
        <mesh filename="model://my_quadruped/meshes/joint_gear_upper_assembly.stl" />
      </geometry>
      <material name="grey"/>
    </visual>
    <collision>
      <origin
        xyz="0 0 0"
        rpy="1.57 0 1.57" />
      <geometry>
        <mesh filename="model://my_quadruped/meshes/joint_gear_upper_assembly.stl" />
      </geometry>
    </collision>
  </link>

  <link name="front_left_d">
    <inertial>
      <mass value="0.5" />
      <inertia ixx="7141392.287E-09" ixy="-13.226E-09"  ixz="-913664.184E-09"
               iyy="7895374.282E-09" iyz="-31.485E-09"
               izz="830881.651E-09" />
    </inertial>
    <visual>
      <origin rpy="1.57 0 1.57" xyz="0 0 0"/>
      <geometry>
        <mesh filename="model://my_quadruped/meshes/Assembly_lower_link_v2.stl" />
      </geometry>
      <material name="grey"/>
    </visual>
    <collision>
      <origin
        xyz="0 0 0"
        rpy="1.57 0 1.57" />
      <geometry>
        <mesh filename="model://my_quadruped/meshes/Assembly_lower_link_v2.stl" />
      </geometry>
    </collision>
  </link>

  <link name="front_right_d">
    <inertial>
      <mass value="0.5" />
      <inertia ixx="7141392.287E-09" ixy="-13.226E-09"  ixz="-913664.184E-09"
               iyy="7895374.282E-09" iyz="-31.485E-09"
               izz="830881.651E-09" />
    </inertial>
    <visual>
      <origin rpy="-1.57 0 -1.57" xyz="0 0 0"/>
      <geometry>
        <mesh filename="model://my_quadruped/meshes/Assembly_lower_link_v2.stl" />
      </geometry>
      <material name="grey"/>
    </visual>
    <collision>
      <origin
        xyz="0 0 0"
        rpy="-1.57 0 -1.57" />
      <geometry>
        <mesh filename="model://my_quadruped/meshes/Assembly_lower_link_v2.stl" />
      </geometry>
    </collision>
  </link>
  
  <link name="back_left_d">
    <inertial>
      <mass value="0.5" />
      <inertia ixx="7141392.287E-09" ixy="-13.226E-09"  ixz="-913664.184E-09"
               iyy="7895374.282E-09" iyz="-31.485E-09"
               izz="830881.651E-09" />
    </inertial>
    <visual>
      <origin rpy="-1.57 0 -1.57" xyz="0 0 0"/>
      <geometry>
        <mesh filename="model://my_quadruped/meshes/Assembly_lower_link_v2.stl" />
      </geometry>
      <material name="grey"/>
    </visual>
    <collision>
      <origin
        xyz="0 0 0"
        rpy="-1.57 0 -1.57" />
      <geometry>
        <mesh filename="model://my_quadruped/meshes/Assembly_lower_link_v2.stl" />
      </geometry>
    </collision>
  </link>
  
  <link name="back_right_d">
    <inertial>
      <mass value="0.5" />
      <inertia ixx="7141392.287E-09" ixy="-13.226E-09"  ixz="-913664.184E-09"
               iyy="7895374.282E-09" iyz="-31.485E-09"
               izz="830881.651E-09" />
    </inertial>
    <visual>
      <origin rpy="1.57 0 1.57" xyz="0 0 0"/>
      <geometry>
        <mesh filename="model://my_quadruped/meshes/Assembly_lower_link_v2.stl" />
      </geometry>
      <material name="grey"/>
    </visual>
    <collision>
      <origin
        xyz="0 0 0"
        rpy="1.57 0 1.57" />
      <geometry>
        <mesh filename="model://my_quadruped/meshes/Assembly_lower_link_v2.stl" />
      </geometry>
    </collision>
  </link>
 
    <joint name="front_right_joint1" type="revolute">
    <limit effort="1000.0" lower="-3.14" upper="3.14" velocity="0.5"/>
    <parent link="body"/>
    <child link="front_right_u"/>
    <origin xyz="0.11 -0.05 0" rpy="0 0 0" />
    <axis xyz="0 1 0" />
  </joint>

  <joint name="front_right_joint2" type="revolute">
    <limit effort="1000.0" lower="-3.14" upper="3.14" velocity="0.5"/>
    <parent link="front_right_u"/>
    <child link="front_right_d"/>
    <origin xyz="0.4 -0.005 0" rpy="0 0 0" />
    <axis xyz="0 1 0" />
  </joint>

  <joint name="front_left_joint1" type="revolute">
    <limit effort="1000.0" lower="-3.14" upper="3.14" velocity="0.5"/>
    <parent link="body"/>
    <child link="front_left_u"/>
    <origin xyz="0.11 0.05 0" rpy="0 0 0" />
    <axis xyz="0 1 0" />
  </joint>

  <joint name="front_left_joint2" type="revolute">
    <limit effort="1000.0" lower="-3.14" upper="3.14" velocity="0.5"/>
    <parent link="front_left_u"/>
    <child link="front_left_d"/>
    <origin xyz="0.4 0.005 0" rpy="0 0 0" />
    <axis xyz="0 1 0" />
  </joint>

  <joint name="back_left_joint1" type="revolute">
    <limit effort="1000.0" lower="-3.14" upper="3.14" velocity="0.5"/>
    <parent link="body"/>
    <child link="back_left_u"/>
    <origin xyz="-0.11 0.05 0" rpy="0 0 3.14" />
    <axis xyz="0 1 0" />
  </joint>

  <joint name="back_left_joint2" type="revolute">
    <limit effort="1000.0" lower="-3.14" upper="3.14" velocity="0.5"/>
    <parent link="back_left_u"/>
    <child link="back_left_d"/>
    <origin xyz="0.4 -0.005 0" rpy="0 0 0" />
    <axis xyz="0 1 0" />
  </joint>

  <joint name="back_right_joint1" type="revolute">
    <limit effort="1000.0" lower="-3.14" upper="3.14" velocity="0.5"/>
    <parent link="body"/>
    <child link="back_right_u"/>
    <origin xyz="-0.11 -0.05 0" rpy="0 0 3.14" />
    <axis xyz="0 1 0" />
  </joint>  

  <joint name="back_right_joint2" type="revolute">
    <limit effort="1000.0" lower="-3.14" upper="3.14" velocity="0.5"/>
    <parent link="back_right_u"/>
    <child link="back_right_d"/>
    <origin xyz="0.4 0.005 0" rpy="0 0 0" />
    <axis xyz="0 1 0" />
  </joint>


</robot>