<?xml version="1.0"?>

<robot xmlns:xacro="http://www.ros.org/wiki/xacro">

  <link name="dummy">
  </link>

  <link name="body">
    <inertial>
      <mass
        value="3" />
      <inertia
        ixx="0.039" ixy="-0.0000173" ixz="0.00929"
        iyy="0.04613" iyz="-0.0000446"
        izz="0.0301" />
    </inertial>
    <visual>
      <origin rpy="0 0 ${pi / 2.0}" xyz="0 0 -0.06"/>
      <geometry>
        <mesh filename="file://$(find quadruped_description)/meshes/frame_aluminum_motor.stl" />
      </geometry>
      <material name="grey"/>
    </visual>
    <collision>
      <origin
        xyz="0 0 -0.06"
        rpy="0 0 ${pi / 2.0}" />
      <geometry>
        <mesh filename="file://$(find quadruped_description)//meshes/frame_aluminum_motor.stl" />
      </geometry>
    </collision>
  </link>
  
  <link
    name="camera_link">
    <inertial>
      <mass
        value="0.05" />
      <inertia
        ixx="0.0000275" ixy="0.000000153" ixz="0.0"
        iyy="0.0000867" iyz="0.0" 
        izz="0.000110" />
    </inertial>
    <visual>
      <origin
        xyz="0 0 0"
        rpy="${pi / 2.0} 0 ${pi / 2.0}" />
      <geometry>
        <mesh
          filename="file://$(find quadruped_description)//meshes/camera_link.stl" />
      </geometry>
      <material
        name="">
        <color
          rgba="0.75294 0.75294 0.75294 1" />
      </material>
    </visual>
    <collision>
      <origin
        xyz="0 0 0"
        rpy="0 0 0" />
      <geometry>
        <mesh
          filename="file://$(find quadruped_description)//meshes/camera_link.stl" />
      </geometry>
    </collision>
  </link>

  <link name="front_left_u">
    <inertial>
      <mass value="0.8" />
      <inertia ixx="0.00051" ixy="0.0025"  ixz="0.0"
               iyy="0.044" iyz="0.0"
               izz="0.044" />
    </inertial>
    <visual>
      <origin rpy="1.57 0 1.57" xyz="0 0 0"/>
      <geometry>
        <mesh filename="file://$(find quadruped_description)//meshes/joint_gear_upper_assembly.stl" />
      </geometry>
      <material name="grey"/>
    </visual>
    <collision>
      <origin
        xyz="0 0 0"
        rpy="1.57 0 1.57" />
      <geometry>
        <mesh filename="file://$(find quadruped_description)//meshes/joint_gear_upper_assembly.stl" />
      </geometry>
    </collision>
  </link>

  <link name="front_right_u">
    <inertial>
      <mass value="0.8" />
      <inertia ixx="0.00076" ixy="-0.00385"  ixz="0.0"
               iyy="0.044" iyz="0.0"
               izz="0.044" />
    </inertial>
    <visual>
      <origin rpy="1.57 3.14 1.57" xyz="0 0 0"/>
      <geometry>
        <mesh filename="file://$(find quadruped_description)//meshes/joint_gear_upper_assembly.stl" />
      </geometry>
      <material name="grey"/>
    </visual>
    <collision>
      <origin
        xyz="0 0 0"
        rpy="1.57 3.14 1.57" />
      <geometry>
        <mesh filename="file://$(find quadruped_description)//meshes/joint_gear_upper_assembly.stl" />
      </geometry>
    </collision>
  </link>

  <link name="back_left_u">
    <inertial>
      <mass value="0.8" />
      <inertia ixx="0.00076" ixy="-0.00385"  ixz="0.0"
               iyy="0.044" iyz="0.0"
               izz="0.044" />
    </inertial>
    <visual>
      <origin rpy="1.57 3.14 1.57" xyz="0 0 0"/>
      <geometry>
        <mesh filename="file://$(find quadruped_description)//meshes/joint_gear_upper_assembly.stl" />
      </geometry>
      <material name="grey"/>
    </visual>
    <collision>
      <origin
        xyz="0 0 0"
        rpy="1.57 3.14 1.57" />
      <geometry>
        <mesh filename="file://$(find quadruped_description)//meshes/joint_gear_upper_assembly.stl" />
      </geometry>
    </collision>
  </link>

  <link name="back_right_u">
    <inertial>
      <mass value="0.8" />
      <inertia ixx="0.00051" ixy="0.0025"  ixz="0.0"
               iyy="0.044" iyz="0.0"
               izz="0.044" />
    </inertial>
    <visual>
      <origin rpy="1.57 0 1.57" xyz="0 0 0"/>
      <geometry>
        <mesh filename="file://$(find quadruped_description)//meshes/joint_gear_upper_assembly.stl" />
      </geometry>
      <material name="grey"/>
    </visual>
    <collision>
      <origin
        xyz="0 0 0"
        rpy="1.57 0 1.57" />
      <geometry>
        <mesh filename="file://$(find quadruped_description)//meshes/joint_gear_upper_assembly.stl" />
      </geometry>
    </collision>
  </link>

  <link name="front_left_d">
    <inertial>
      <mass value="1.0" />
      <!-- <inertia ixx="0.0039" ixy="0.012"  ixz="0.0"
               iyy="0.1412" iyz="0.0"
               izz="0.1447" /> Pata nueva-->
      <inertia ixx="0.0009" ixy="0.0038"  ixz="0.0"
               iyy="0.044" iyz="0.0"
               izz="0.0457" />
    </inertial>
    <visual>
      <origin rpy="1.57 0 1.57" xyz="0 0 0"/>
      <geometry>
        <mesh filename="file://$(find quadruped_description)//meshes/Assembly_lower_link_v2.stl" />
      </geometry>
      <material name="grey"/>
    </visual>
    <collision>
      <origin
        xyz="0 0 0"
        rpy="1.57 0 1.57" />
      <geometry>
        <mesh filename="file://$(find quadruped_description)//meshes/Assembly_lower_link_v2.stl" />
      </geometry>
    </collision>
  </link>

  <link name="front_right_d">
    <inertial>
      <mass value="1.0" />
      <inertia ixx="0.0009" ixy="-0.0038"  ixz="0.0"
               iyy="0.044" iyz="0.0"
               izz="0.0457" />
    </inertial>
    <visual>
      <origin rpy="-1.57 0 -1.57" xyz="0 0 0"/>
      <geometry>
        <mesh filename="file://$(find quadruped_description)//meshes/Assembly_lower_link_v2.stl" />
      </geometry>
      <material name="grey"/>
    </visual>
    <collision>
      <origin
        xyz="0 0 0"
        rpy="-1.57 0 -1.57" />
      <geometry>
        <mesh filename="file://$(find quadruped_description)//meshes/Assembly_lower_link_v2.stl" />
      </geometry>
    </collision>
  </link>
  
  <link name="back_left_d">
    <inertial>
      <mass value="1.0" />
      <inertia ixx="0.0009" ixy="-0.0038"  ixz="0.0"
               iyy="0.044" iyz="0.0"
               izz="0.0457" />
    </inertial>
    <visual>
      <origin rpy="-1.57 0 -1.57" xyz="0 0 0"/>
      <geometry>
        <mesh filename="file://$(find quadruped_description)//meshes/Assembly_lower_link_v2.stl" />
      </geometry>
      <material name="grey"/>
    </visual>
    <collision>
      <origin
        xyz="0 0 0"
        rpy="-1.57 0 -1.57" />
      <geometry>
        <mesh filename="file://$(find quadruped_description)//meshes/Assembly_lower_link_v2.stl" />
      </geometry>
    </collision>
  </link>
  
  <link name="back_right_d">
    <inertial>
      <mass value="1.0" />
      <inertia ixx="0.0009" ixy="0.0038"  ixz="0.0"
               iyy="0.044" iyz="0.0"
               izz="0.0457" />
    </inertial>
    <visual>
      <origin rpy="1.57 0 1.57" xyz="0 0 0"/>
      <geometry>
        <mesh filename="file://$(find quadruped_description)//meshes/Assembly_lower_link_v2.stl" />
      </geometry>
      <material name="grey"/>
    </visual>
    <collision>
      <origin
        xyz="0 0 0"
        rpy="1.57 0 1.57" />
      <geometry>
        <mesh filename="file://$(find quadruped_description)//meshes/Assembly_lower_link_v2.stl" />
      </geometry>
    </collision>
  </link>

  <joint name="dummy_joint" type="fixed">
     <parent link="dummy"/>
     <child link="body"/>
  </joint>

  <joint
    name="camera_joint" type="revolute">
    <origin
      xyz="0.2 0 0.42525"
      rpy="0 0 0" />
    <parent
      link="body" />
    <child
      link="camera_link" />
    <axis
      xyz="0 1 0" />
    <limit
      lower="-3.14"
      upper="3.14"
      effort="100"
      velocity="100" />
  </joint> 
 
    <joint name="front_right_joint1" type="revolute">
    <limit effort="1000.0" lower="-3.14" upper="3.14" velocity="0.5"/>
    <parent link="body"/>
    <child link="front_right_u"/>
    <origin xyz="0.11 -0.05 0" rpy="0 0 0" />
    <axis xyz="0 1 0" />
  </joint>

  <joint name="front_right_joint2" type="revolute">
    <limit effort="1000.0" lower="-3.14" upper="3.14" velocity="0.5"/>
    <parent link="front_right_u"/>
    <child link="front_right_d"/>
    <origin xyz="0.4 -0.005 0" rpy="0 0 0" />
    <axis xyz="0 1 0" />
  </joint>

  <joint name="front_left_joint1" type="revolute">
    <limit effort="1000.0" lower="-3.14" upper="3.14" velocity="0.5"/>
    <parent link="body"/>
    <child link="front_left_u"/>
    <origin xyz="0.11 0.05 0" rpy="0 0 0" />
    <axis xyz="0 1 0" />
  </joint>

  <joint name="front_left_joint2" type="revolute">
    <limit effort="1000.0" lower="-3.14" upper="3.14" velocity="0.5"/>
    <parent link="front_left_u"/>
    <child link="front_left_d"/>
    <origin xyz="0.4 0.005 0" rpy="0 0 0" />
    <axis xyz="0 1 0" />
  </joint>

  <joint name="back_left_joint1" type="revolute">
    <limit effort="1000.0" lower="-3.14" upper="3.14" velocity="0.5"/>
    <parent link="body"/>
    <child link="back_left_u"/>
    <origin xyz="-0.11 0.05 0" rpy="0 0 3.14" />
    <axis xyz="0 1 0" />
  </joint>

  <joint name="back_left_joint2" type="revolute">
    <limit effort="1000.0" lower="-3.14" upper="3.14" velocity="0.5"/>
    <parent link="back_left_u"/>
    <child link="back_left_d"/>
    <origin xyz="0.4 -0.005 0" rpy="0 0 0" />
    <axis xyz="0 1 0" />
  </joint>

  <joint name="back_right_joint1" type="revolute">
    <limit effort="1000.0" lower="-3.14" upper="3.14" velocity="0.5"/>
    <parent link="body"/>
    <child link="back_right_u"/>
    <origin xyz="-0.11 -0.05 0" rpy="0 0 3.14" />
    <axis xyz="0 1 0" />
  </joint>  

  <joint name="back_right_joint2" type="revolute">
    <limit effort="1000.0" lower="-3.14" upper="3.14" velocity="0.5"/>
    <parent link="back_right_u"/>
    <child link="back_right_d"/>
    <origin xyz="0.4 0.005 0" rpy="0 0 0" />
    <axis xyz="0 1 0" />
  </joint> 

</robot>